##  -*- python -*-  
# db file automatically generated by genconf on: Tue Mar 30 08:59:39 2010
## insulates outside world against anything bad that could happen
## also prevents global scope pollution
def _fillCfgDb():
    from GaudiKernel.Proxy.ConfigurableDb import CfgDb

    # get a handle on the repository of Configurables
    cfgDb = CfgDb()

    # populate the repository with informations on Configurables 

    cfgDb.add( configurable = 'VeloPixChecker',
               package = 'RecoUpgradeMC',
               module  = 'RecoUpgradeMC.RecoUpgradeMCConf',
               lib     = 'RecoUpgradeMC' )
    cfgDb.add( configurable = 'TrackAssociatorUpgrade',
               package = 'RecoUpgradeMC',
               module  = 'RecoUpgradeMC.RecoUpgradeMCConf',
               lib     = 'RecoUpgradeMC' )
    cfgDb.add( configurable = 'PatLHCbIDUp2MCParticle',
               package = 'RecoUpgradeMC',
               module  = 'RecoUpgradeMC.RecoUpgradeMCConf',
               lib     = 'RecoUpgradeMC' )
    cfgDb.add( configurable = 'PatLHCbIDUp2MCHit',
               package = 'RecoUpgradeMC',
               module  = 'RecoUpgradeMC.RecoUpgradeMCConf',
               lib     = 'RecoUpgradeMC' )
    cfgDb.add( configurable = 'CheatedVeloPixPat',
               package = 'RecoUpgradeMC',
               module  = 'RecoUpgradeMC.RecoUpgradeMCConf',
               lib     = 'RecoUpgradeMC' )
    return #_fillCfgDb
# fill cfgDb at module import...
try:
    _fillCfgDb()
    #house cleaning...
    del _fillCfgDb
except Exception,err:
    print "Py:ConfigurableDb   ERROR Problem with [%s] content!" % __name__
    print "Py:ConfigurableDb   ERROR",err
    print "Py:ConfigurableDb   ERROR   ==> culprit is package [RecoUpgradeMC] !"
